Workbook

Sheet Line productivity
A1: Date | B1: Product | C1: Batch | D1: Operator | E1: Start Time | F1: End Time
A2: 45533 | B2: OR-600 | C2: 422111 | D2: Mac | E2: 0.49305556 | F2: 0.58680556
A3: 45533 | B3: LE-600 | C3: 422112 | D3: Mac | E3: 0.58680556 | F3: 0.65625
A4: 45533 | B4: LE-600 | C4: 422113 | D4: Mac | E4: 0.65625 | F4: 0.73263889
A5: 45533 | B5: LE-600 | C5: 422114 | D5: Mac | E5: 0.73263889 | F5: 0.80208333
A6: 45533 | B6: LE-600 | C6: 422115 | D6: Charlie | E6: 0.80208333 | F6: 0.86041667
A7: 45533 | B7: LE-600 | C7: 422116 | D7: Charlie | E7: 0.86041667 | F7: 0.90208333
A8: 45533 | B8: LE-600 | C8: 422117 | D8: Charlie | E8: 0.90208333 | F8: 0.95416667
A9: 45534 | B9: CO-600 | C9: 422118 | D9: Dee | E9: 0.17013889 | F9: 0.25347222
A10: 45534 | B10: CO-600 | C10: 422119 | D10: Dee | E10: 0.25347222 | F10: 0.3125
A11: 45534 | B11: CO-600 | C11: 422120 | D11: Dee | E11: 0.3125 | F11: 0.39027778
A12: 45534 | B12: CO-600 | C12: 422121 | D12: Dennis | E12: 0.39027778 | F12: 0.44236111
A13: 45534 | B13: CO-600 | C13: 422122 | D13: Dennis | E13: 0.44236111 | F13: 0.50138889
... A39: 45538 | B39: CO-2L | C39: 422148 | D39: Mac | E39: 0.95486111 | F39: 1.0451389

Sheet Products
A1: Product | B1: Flavor | C1: Size | D1: Min batch time
A2: OR-600 | B2: Orange | C2: 600 ml | D2: 60
A3: LE-600 | B3: Lemon lime | C3: 600 ml | D3: 60
A4: CO-600 | B4: Cola | C4: 600 ml | D4: 60
A5: DC-600 | B5: Diet Cola | C5: 600 ml | D5: 60
A6: RB-600 | B6: Root Beer | C6: 600 ml | D6: 60
A7: CO-2L | B7: Cola | C7: 2 L | D7: 98

Sheet Downtime factors
A1: Factor | B1: Description | C1: Operator Error
A2: 1 | B2: Emergency stop | C2: No
A3: 2 | B3: Batch change | C3: Yes
A4: 3 | B4: Labeling error | C4: No
A5: 4 | B5: Inventory shortage | C5: No
A6: 5 | B6: Product spill | C6: Yes
A7: 6 | B7: Machine adjustment | C7: Yes
A8: 7 | B8: Machine failure | C8: No
A9: 8 | B9: Batch coding error | C9: Yes
A10: 9 | B10: Conveyor belt jam | C10: No
A11: 10 | B11: Calibration error | C11: Yes
A12: 11 | B12: Label switch | C12: Yes
A13: 12 | B13: Other | C13: No

Sheet Line downtime
B1: Downtime factor
A2: Batch | B2: 1 | C2: 2 | D2: 3 | E2: 4 | F2: 5 | G2: 6 | H2: 7 | I2: 8 | J2: 9 | K2: 10 | L2: 11 | M2: 12
A3: 422111 | C3: 60 | H3: 15
A4: 422112 | C4: 20 | I4: 20
A5: 422113 | C5: 50
A6: 422114 | E6: 25 | G6: 15
A7: 422115 | K7: 24
A8: 422116
A9: 422117 | C9: 10 | G9: 5
A10: 422118 | G10: 14 | H10: 16 | L10: 10 | M10: 20
A11: 422119 | E11: 25
A12: 422120 | E12: 20 | F12: 15 | J12: 17
A13: 422121 | H13: 15
A14: 422122 | H14: 25
A15: 422123 | E15: 43 | H15: 30
A16: 422124 | F16: 20 | G16: 20
A17: 422125 | L17: 10 | M17: 10
A18: 422126 | I18: 44
A19: 422127 | G19: 23
A20: 422128 | F20: 22 | H20: 30
A21: 422129 | M21: 15
A22: 422130 | C22: 20
A23: 422131 | E23: 20 | K23: 10
A24: 422132
A25: 422133 | H25: 20
A26: 422134 | H26: 30 | I26: 20
A27: 422135 | E27: 30 | M27: 15
A28: 422136
A29: 422137 | I29: 30 | K29: 15
A30: 422138 | D30: 20
A31: 422139 | E31: 20 | G31: 15
A32: 422140 | G32: 50 | L32: 13
A33: 422141 | M33: 7
A34: 422142 | G34: 30
A35: 422143 | G35: 40 | H35: 18
A36: 422144 | G36: 30 | I36: 24
A37: 422145 | D37: 22
A38: 422146 | G38: 30 | H38: 25 | M38: 7
A39: 422147 | E39: 17 | G39: 60 | H39: 30
A40: 422148 | E40: 25 | I40: 7
...

Sheet Analysis
A1: Date | B1: Product | C1: Batch | D1: Operator | E1: Start Time | F1: End Time | G1: Actual Duration | H1: Min Batch Time | I1: Efficiency % | J1: Total Downtime (min) | K1: Eficiency w/o Downtime % | L1: Batch Change (F2) | M1: Product Spill (F5) | N1: Machine Adj (F6) | O1: Batch Code Error (F8) | P1: Calibration Error (F10) | Q1: Label Switch (F11)
A2: 45533 | B2: OR-600 | C2: 422111 | D2: Mac | E2: 0.49305556 | F2: 0.58680556 | G2: =HOUR(F2-E2)*60+MINUTE(F2-E2) -> 135 | H2: =VLOOKUP(B2,Products!A:D,4,FALSE) -> 60 | I2: =H2/G2 -> 0.44444444 | J2: =IFERROR(VLOOKUP(C2,'Line downtime'!A:M,2,FALSE),0)+IFERROR(VLOOKUP(C2,'Line downtime'!A:M,3,FALSE),0)+IFERROR(VLOOKUP(C2,'Line downtime'!A:M,4,FALSE),0)+IFERROR(VLOOKUP(C2,'Line downtime'!A:M,5,FALSE),0)+IFERROR(VLOOKUP(C2,'Line downtime'!A:M,6,FALSE),0)+IFERROR(VLOOKUP(C2,'Line downtime'!A:M,7,FALSE),0)+IFERROR(VLOOKUP(C2,'Line downtime'!A:M,8,FALSE),0)+IFERROR(VLOOKUP(C2,'Line downtime'!A:M,9,FALSE),0)+IFERROR(VLOOKUP(C2,'Line downtime'!A:M,10,FALSE),0)+IFERROR(VLOOKUP(C2,'Line downtime'!A:M,11,FALSE),0)+IFERROR(VLOOKUP(C2,'Line downtime'!A:M,12,FALSE),0)+IFERROR(VLOOKUP(C2,'Line downtime'!A:M,13,FALSE),0) -> 75 | K2: =H2/(G2-J2) -> 1 | L2: =IFERROR(VLOOKUP($C2,'Line downtime'!$A:$M,3,FALSE),0) -> 60 | M2: =IFERROR(VLOOKUP($C2,'Line downtime'!$A:$M,6,FALSE),0) -> 0 | N2: =IFERROR(VLOOKUP($C2,'Line downtime'!$A:$M,7,FALSE),0) -> 0 | O2: =IFERROR(VLOOKUP($C2,'Line downtime'!$A:$M,9,FALSE),0) -> 0 | P2: =IFERROR(VLOOKUP($C2,'Line downtime'!$A:$M,11,FALSE),0) -> 0 | Q2: =IFERROR(VLOOKUP($C2,'Line downtime'!$A:$M,12,FALSE),0) -> 0
A3: 45533 | B3: LE-600 | C3: 422112 | D3: Mac | E3: 0.58680556 | F3: 0.65625 | G3: =HOUR(F3-E3)*60+MINUTE(F3-E3) -> 100 | H3: =VLOOKUP(B3,Products!A:D,4,FALSE) -> 60 | I3: =H3/G3 -> 0.6 | J3: =IFERROR(VLOOKUP(C3,'Line downtime'!A:M,2,FALSE),0)+IFERROR(VLOOKUP(C3,'Line downtime'!A:M,3,FALSE),0)+IFERROR(VLOOKUP(C3,'Line downtime'!A:M,4,FALSE),0)+IFERROR(VLOOKUP(C3,'Line downtime'!A:M,5,FALSE),0)+IFERROR(VLOOKUP(C3,'Line downtime'!A:M,6,FALSE),0)+IFERROR(VLOOKUP(C3,'Line downtime'!A:M,7,FALSE),0)+IFERROR(VLOOKUP(C3,'Line downtime'!A:M,8,FALSE),0)+IFERROR(VLOOKUP(C3,'Line downtime'!A:M,9,FALSE),0)+IFERROR(VLOOKUP(C3,'Line downtime'!A:M,10,FALSE),0)+IFERROR(VLOOKUP(C3,'Line downtime'!A:M,11,FALSE),0)+IFERROR(VLOOKUP(C3,'Line downtime'!A:M,12,FALSE),0)+IFERROR(VLOOKUP(C3,'Line downtime'!A:M,13,FALSE),0) -> 40 | K3: =H3/(G3-J3) -> 1 | L3: =IFERROR(VLOOKUP($C3,'Line downtime'!$A:$M,3,FALSE),0) -> 20 | M3: =IFERROR(VLOOKUP($C3,'Line downtime'!$A:$M,6,FALSE),0) -> 0 | N3: =IFERROR(VLOOKUP($C3,'Line downtime'!$A:$M,7,FALSE),0) -> 0 | O3: =IFERROR(VLOOKUP($C3,'Line downtime'!$A:$M,9,FALSE),0) -> 20 | P3: =IFERROR(VLOOKUP($C3,'Line downtime'!$A:$M,11,FALSE),0) -> 0 | Q3: =IFERROR(VLOOKUP($C3,'Line downtime'!$A:$M,12,FALSE),0) -> 0
A4: 45533 | B4: LE-600 | C4: 422113 | D4: Mac | E4: 0.65625 | F4: 0.73263889 | G4: =HOUR(F4-E4)*60+MINUTE(F4-E4) -> 110 | H4: =VLOOKUP(B4,Products!A:D,4,FALSE) -> 60 | I4: =H4/G4 -> 0.54545455 | J4: =IFERROR(VLOOKUP(C4,'Line downtime'!A:M,2,FALSE),0)+IFERROR(VLOOKUP(C4,'Line downtime'!A:M,3,FALSE),0)+IFERROR(VLOOKUP(C4,'Line downtime'!A:M,4,FALSE),0)+IFERROR(VLOOKUP(C4,'Line downtime'!A:M,5,FALSE),0)+IFERROR(VLOOKUP(C4,'Line downtime'!A:M,6,FALSE),0)+IFERROR(VLOOKUP(C4,'Line downtime'!A:M,7,FALSE),0)+IFERROR(VLOOKUP(C4,'Line downtime'!A:M,8,FALSE),0)+IFERROR(VLOOKUP(C4,'Line downtime'!A:M,9,FALSE),0)+IFERROR(VLOOKUP(C4,'Line downtime'!A:M,10,FALSE),0)+IFERROR(VLOOKUP(C4,'Line downtime'!A:M,11,FALSE),0)+IFERROR(VLOOKUP(C4,'Line downtime'!A:M,12,FALSE),0)+IFERROR(VLOOKUP(C4,'Line downtime'!A:M,13,FALSE),0) -> 50 | K4: =H4/(G4-J4) -> 1 | L4: =IFERROR(VLOOKUP($C4,'Line downtime'!$A:$M,3,FALSE),0) -> 50 | M4: =IFERROR(VLOOKUP($C4,'Line downtime'!$A:$M,6,FALSE),0) -> 0 | N4: =IFERROR(VLOOKUP($C4,'Line downtime'!$A:$M,7,FALSE),0) -> 0 | O4: =IFERROR(VLOOKUP($C4,'Line downtime'!$A:$M,9,FALSE),0) -> 0 | P4: =IFERROR(VLOOKUP($C4,'Line downtime'!$A:$M,11,FALSE),0) -> 0 | Q4: =IFERROR(VLOOKUP($C4,'Line downtime'!$A:$M,12,FALSE),0) -> 0
A5: 45533 | B5: LE-600 | C5: 422114 | D5: Mac | E5: 0.73263889 | F5: 0.80208333 | G5: =HOUR(F5-E5)*60+MINUTE(F5-E5) -> 100 | H5: =VLOOKUP(B5,Products!A:D,4,FALSE) -> 60 | I5: =H5/G5 -> 0.6 | J5: =IFERROR(VLOOKUP(C5,'Line downtime'!A:M,2,FALSE),0)+IFERROR(VLOOKUP(C5,'Line downtime'!A:M,3,FALSE),0)+IFERROR(VLOOKUP(C5,'Line downtime'!A:M,4,FALSE),0)+IFERROR(VLOOKUP(C5,'Line downtime'!A:M,5,FALSE),0)+IFERROR(VLOOKUP(C5,'Line downtime'!A:M,6,FALSE),0)+IFERROR(VLOOKUP(C5,'Line downtime'!A:M,7,FALSE),0)+IFERROR(VLOOKUP(C5,'Line downtime'!A:M,8,FALSE),0)+IFERROR(VLOOKUP(C5,'Line downtime'!A:M,9,FALSE),0)+IFERROR(VLOOKUP(C5,'Line downtime'!A:M,10,FALSE),0)+IFERROR(VLOOKUP(C5,'Line downtime'!A:M,11,FALSE),0)+IFERROR(VLOOKUP(C5,'Line downtime'!A:M,12,FALSE),0)+IFERROR(VLOOKUP(C5,'Line downtime'!A:M,13,FALSE),0) -> 40 | K5: =H5/(G5-J5) -> 1 | L5: =IFERROR(VLOOKUP($C5,'Line downtime'!$A:$M,3,FALSE),0) -> 0 | M5: =IFERROR(VLOOKUP($C5,'Line downtime'!$A:$M,6,FALSE),0) -> 0 | N5: =IFERROR(VLOOKUP($C5,'Line downtime'!$A:$M,7,FALSE),0) -> 15 | O5: =IFERROR(VLOOKUP($C5,'Line downtime'!$A:$M,9,FALSE),0) -> 0 | P5: =IFERROR(VLOOKUP($C5,'Line downtime'!$A:$M,11,FALSE),0) -> 0 | Q5: =IFERROR(VLOOKUP($C5,'Line downtime'!$A:$M,12,FALSE),0) -> 0
A6: 45533 | B6: LE-600 | C6: 422115 | D6: Charlie | E6: 0.80208333 | F6: 0.86041667 | G6: =HOUR(F6-E6)*60+MINUTE(F6-E6) -> 84 | H6: =VLOOKUP(B6,Products!A:D,4,FALSE) -> 60 | I6: =H6/G6 -> 0.71428571 | J6: =IFERROR(VLOOKUP(C6,'Line downtime'!A:M,2,FALSE),0)+IFERROR(VLOOKUP(C6,'Line downtime'!A:M,3,FALSE),0)+IFERROR(VLOOKUP(C6,'Line downtime'!A:M,4,FALSE),0)+IFERROR(VLOOKUP(C6,'Line downtime'!A:M,5,FALSE),0)+IFERROR(VLOOKUP(C6,'Line downtime'!A:M,6,FALSE),0)+IFERROR(VLOOKUP(C6,'Line downtime'!A:M,7,FALSE),0)+IFERROR(VLOOKUP(C6,'Line downtime'!A:M,8,FALSE),0)+IFERROR(VLOOKUP(C6,'Line downtime'!A:M,9,FALSE),0)+IFERROR(VLOOKUP(C6,'Line downtime'!A:M,10,FALSE),0)+IFERROR(VLOOKUP(C6,'Line downtime'!A:M,11,FALSE),0)+IFERROR(VLOOKUP(C6,'Line downtime'!A:M,12,FALSE),0)+IFERROR(VLOOKUP(C6,'Line downtime'!A:M,13,FALSE),0) -> 24 | K6: =H6/(G6-J6) -> 1 | L6: =IFERROR(VLOOKUP($C6,'Line downtime'!$A:$M,3,FALSE),0) -> 0 | M6: =IFERROR(VLOOKUP($C6,'Line downtime'!$A:$M,6,FALSE),0) -> 0 | N6: =IFERROR(VLOOKUP($C6,'Line downtime'!$A:$M,7,FALSE),0) -> 0 | O6: =IFERROR(VLOOKUP($C6,'Line downtime'!$A:$M,9,FALSE),0) -> 0 | P6: =IFERROR(VLOOKUP($C6,'Line downtime'!$A:$M,11,FALSE),0) -> 24 | Q6: =IFERROR(VLOOKUP($C6,'Line downtime'!$A:$M,12,FALSE),0) -> 0
A7: 45533 | B7: LE-600 | C7: 422116 | D7: Charlie | E7: 0.86041667 | F7: 0.90208333 | G7: =HOUR(F7-E7)*60+MINUTE(F7-E7) -> 60 | H7: =VLOOKUP(B7,Products!A:D,4,FALSE) -> 60 | I7: =H7/G7 -> 1 | J7: =IFERROR(VLOOKUP(C7,'Line downtime'!A:M,2,FALSE),0)+IFERROR(VLOOKUP(C7,'Line downtime'!A:M,3,FALSE),0)+IFERROR(VLOOKUP(C7,'Line downtime'!A:M,4,FALSE),0)+IFERROR(VLOOKUP(C7,'Line downtime'!A:M,5,FALSE),0)+IFERROR(VLOOKUP(C7,'Line downtime'!A:M,6,FALSE),0)+IFERROR(VLOOKUP(C7,'Line downtime'!A:M,7,FALSE),0)+IFERROR(VLOOKUP(C7,'Line downtime'!A:M,8,FALSE),0)+IFERROR(VLOOKUP(C7,'Line downtime'!A:M,9,FALSE),0)+IFERROR(VLOOKUP(C7,'Line downtime'!A:M,10,FALSE),0)+IFERROR(VLOOKUP(C7,'Line downtime'!A:M,11,FALSE),0)+IFERROR(VLOOKUP(C7,'Line downtime'!A:M,12,FALSE),0)+IFERROR(VLOOKUP(C7,'Line downtime'!A:M,13,FALSE),0) -> 0 | K7: =H7/(G7-J7) -> 1 | L7: =IFERROR(VLOOKUP($C7,'Line downtime'!$A:$M,3,FALSE),0) -> 0 | M7: =IFERROR(VLOOKUP($C7,'Line downtime'!$A:$M,6,FALSE),0) -> 0 | N7: =IFERROR(VLOOKUP($C7,'Line downtime'!$A:$M,7,FALSE),0) -> 0 | O7: =IFERROR(VLOOKUP($C7,'Line downtime'!$A:$M,9,FALSE),0) -> 0 | P7: =IFERROR(VLOOKUP($C7,'Line downtime'!$A:$M,11,FALSE),0) -> 0 | Q7: =IFERROR(VLOOKUP($C7,'Line downtime'!$A:$M,12,FALSE),0) -> 0
A8: 45533 | B8: LE-600 | C8: 422117 | D8: Charlie | E8: 0.90208333 | F8: 0.95416667 | G8: =HOUR(F8-E8)*60+MINUTE(F8-E8) -> 75 | H8: =VLOOKUP(B8,Products!A:D,4,FALSE) -> 60 | I8: =H8/G8 -> 0.8 | J8: =IFERROR(VLOOKUP(C8,'Line downtime'!A:M,2,FALSE),0)+IFERROR(VLOOKUP(C8,'Line downtime'!A:M,3,FALSE),0)+IFERROR(VLOOKUP(C8,'Line downtime'!A:M,4,FALSE),0)+IFERROR(VLOOKUP(C8,'Line downtime'!A:M,5,FALSE),0)+IFERROR(VLOOKUP(C8,'Line downtime'!A:M,6,FALSE),0)+IFERROR(VLOOKUP(C8,'Line downtime'!A:M,7,FALSE),0)+IFERROR(VLOOKUP(C8,'Line downtime'!A:M,8,FALSE),0)+IFERROR(VLOOKUP(C8,'Line downtime'!A:M,9,FALSE),0)+IFERROR(VLOOKUP(C8,'Line downtime'!A:M,10,FALSE),0)+IFERROR(VLOOKUP(C8,'Line downtime'!A:M,11,FALSE),0)+IFERROR(VLOOKUP(C8,'Line downtime'!A:M,12,FALSE),0)+IFERROR(VLOOKUP(C8,'Line downtime'!A:M,13,FALSE),0) -> 15 | K8: =H8/(G8-J8) -> 1 | L8: =IFERROR(VLOOKUP($C8,'Line downtime'!$A:$M,3,FALSE),0) -> 10 | M8: =IFERROR(VLOOKUP($C8,'Line downtime'!$A:$M,6,FALSE),0) -> 0 | N8: =IFERROR(VLOOKUP($C8,'Line downtime'!$A:$M,7,FALSE),0) -> 5 | O8: =IFERROR(VLOOKUP($C8,'Line downtime'!$A:$M,9,FALSE),0) -> 0 | P8: =IFERROR(VLOOKUP($C8,'Line downtime'!$A:$M,11,FALSE),0) -> 0 | Q8: =IFERROR(VLOOKUP($C8,'Line downtime'!$A:$M,12,FALSE),0) -> 0
A9: 45534 | B9: CO-600 | C9: 422118 | D9: Dee | E9: 0.17013889 | F9: 0.25347222 | G9: =HOUR(F9-E9)*60+MINUTE(F9-E9) -> 120 | H9: =VLOOKUP(B9,Products!A:D,4,FALSE) -> 60 | I9: =H9/G9 -> 0.5 | J9: =IFERROR(VLOOKUP(C9,'Line downtime'!A:M,2,FALSE),0)+IFERROR(VLOOKUP(C9,'Line downtime'!A:M,3,FALSE),0)+IFERROR(VLOOKUP(C9,'Line downtime'!A:M,4,FALSE),0)+IFERROR(VLOOKUP(C9,'Line downtime'!A:M,5,FALSE),0)+IFERROR(VLOOKUP(C9,'Line downtime'!A:M,6,FALSE),0)+IFERROR(VLOOKUP(C9,'Line downtime'!A:M,7,FALSE),0)+IFERROR(VLOOKUP(C9,'Line downtime'!A:M,8,FALSE),0)+IFERROR(VLOOKUP(C9,'Line downtime'!A:M,9,FALSE),0)+IFERROR(VLOOKUP(C9,'Line downtime'!A:M,10,FALSE),0)+IFERROR(VLOOKUP(C9,'Line downtime'!A:M,11,FALSE),0)+IFERROR(VLOOKUP(C9,'Line downtime'!A:M,12,FALSE),0)+IFERROR(VLOOKUP(C9,'Line downtime'!A:M,13,FALSE),0) -> 60 | K9: =H9/(G9-J9) -> 1 | L9: =IFERROR(VLOOKUP($C9,'Line downtime'!$A:$M,3,FALSE),0) -> 0 | M9: =IFERROR(VLOOKUP($C9,'Line downtime'!$A:$M,6,FALSE),0) -> 0 | N9: =IFERROR(VLOOKUP($C9,'Line downtime'!$A:$M,7,FALSE),0) -> 14 | O9: =IFERROR(VLOOKUP($C9,'Line downtime'!$A:$M,9,FALSE),0) -> 0 | P9: =IFERROR(VLOOKUP($C9,'Line downtime'!$A:$M,11,FALSE),0) -> 0 | Q9: =IFERROR(VLOOKUP($C9,'Line downtime'!$A:$M,12,FALSE),0) -> 10
A10: 45534 | B10: CO-600 | C10: 422119 | D10: Dee | E10: 0.25347222 | F10: 0.3125 | G10: =HOUR(F10-E10)*60+MINUTE(F10-E10) -> 85 | H10: =VLOOKUP(B10,Products!A:D,4,FALSE) -> 60 | I10: =H10/G10 -> 0.70588235 | J10: =IFERROR(VLOOKUP(C10,'Line downtime'!A:M,2,FALSE),0)+IFERROR(VLOOKUP(C10,'Line downtime'!A:M,3,FALSE),0)+IFERROR(VLOOKUP(C10,'Line downtime'!A:M,4,FALSE),0)+IFERROR(VLOOKUP(C10,'Line downtime'!A:M,5,FALSE),0)+IFERROR(VLOOKUP(C10,'Line downtime'!A:M,6,FALSE),0)+IFERROR(VLOOKUP(C10,'Line downtime'!A:M,7,FALSE),0)+IFERROR(VLOOKUP(C10,'Line downtime'!A:M,8,FALSE),0)+IFERROR(VLOOKUP(C10,'Line downtime'!A:M,9,FALSE),0)+IFERROR(VLOOKUP(C10,'Line downtime'!A:M,10,FALSE),0)+IFERROR(VLOOKUP(C10,'Line downtime'!A:M,11,FALSE),0)+IFERROR(VLOOKUP(C10,'Line downtime'!A:M,12,FALSE),0)+IFERROR(VLOOKUP(C10,'Line downtime'!A:M,13,FALSE),0) -> 25 | K10: =H10/(G10-J10) -> 1 | L10: =IFERROR(VLOOKUP($C10,'Line downtime'!$A:$M,3,FALSE),0) -> 0 | M10: =IFERROR(VLOOKUP($C10,'Line downtime'!$A:$M,6,FALSE),0) -> 0 | N10: =IFERROR(VLOOKUP($C10,'Line downtime'!$A:$M,7,FALSE),0) -> 0 | O10: =IFERROR(VLOOKUP($C10,'Line downtime'!$A:$M,9,FALSE),0) -> 0 | P10: =IFERROR(VLOOKUP($C10,'Line downtime'!$A:$M,11,FALSE),0) -> 0 | Q10: =IFERROR(VLOOKUP($C10,'Line downtime'!$A:$M,12,FALSE),0) -> 0
A11: 45534 | B11: CO-600 | C11: 422120 | D11: Dee | E11: 0.3125 | F11: 0.39027778 | G11: =HOUR(F11-E11)*60+MINUTE(F11-E11) -> 112 | H11: =VLOOKUP(B11,Products!A:D,4,FALSE) -> 60 | I11: =H11/G11 -> 0.53571429 | J11: =IFERROR(VLOOKUP(C11,'Line downtime'!A:M,2,FALSE),0)+IFERROR(VLOOKUP(C11,'Line downtime'!A:M,3,FALSE),0)+IFERROR(VLOOKUP(C11,'Line downtime'!A:M,4,FALSE),0)+IFERROR(VLOOKUP(C11,'Line downtime'!A:M,5,FALSE),0)+IFERROR(VLOOKUP(C11,'Line downtime'!A:M,6,FALSE),0)+IFERROR(VLOOKUP(C11,'Line downtime'!A:M,7,FALSE),0)+IFERROR(VLOOKUP(C11,'Line downtime'!A:M,8,FALSE),0)+IFERROR(VLOOKUP(C11,'Line downtime'!A:M,9,FALSE),0)+IFERROR(VLOOKUP(C11,'Line downtime'!A:M,10,FALSE),0)+IFERROR(VLOOKUP(C11,'Line downtime'!A:M,11,FALSE),0)+IFERROR(VLOOKUP(C11,'Line downtime'!A:M,12,FALSE),0)+IFERROR(VLOOKUP(C11,'Line downtime'!A:M,13,FALSE),0) -> 52 | K11: =H11/(G11-J11) -> 1 | L11: =IFERROR(VLOOKUP($C11,'Line downtime'!$A:$M,3,FALSE),0) -> 0 | M11: =IFERROR(VLOOKUP($C11,'Line downtime'!$A:$M,6,FALSE),0) -> 15 | N11: =IFERROR(VLOOKUP($C11,'Line downtime'!$A:$M,7,FALSE),0) -> 0 | O11: =IFERROR(VLOOKUP($C11,'Line downtime'!$A:$M,9,FALSE),0) -> 0 | P11: =IFERROR(VLOOKUP($C11,'Line downtime'!$A:$M,11,FALSE),0) -> 0 | Q11: =IFERROR(VLOOKUP($C11,'Line downtime'!$A:$M,12,FALSE),0) -> 0
A12: 45534 | B12: CO-600 | C12: 422121 | D12: Dennis | E12: 0.39027778 | F12: 0.44236111 | G12: =HOUR(F12-E12)*60+MINUTE(F12-E12) -> 75 | H12: =VLOOKUP(B12,Products!A:D,4,FALSE) -> 60 | I12: =H12/G12 -> 0.8 | J12: =IFERROR(VLOOKUP(C12,'Line downtime'!A:M,2,FALSE),0)+IFERROR(VLOOKUP(C12,'Line downtime'!A:M,3,FALSE),0)+IFERROR(VLOOKUP(C12,'Line downtime'!A:M,4,FALSE),0)+IFERROR(VLOOKUP(C12,'Line downtime'!A:M,5,FALSE),0)+IFERROR(VLOOKUP(C12,'Line downtime'!A:M,6,FALSE),0)+IFERROR(VLOOKUP(C12,'Line downtime'!A:M,7,FALSE),0)+IFERROR(VLOOKUP(C12,'Line downtime'!A:M,8,FALSE),0)+IFERROR(VLOOKUP(C12,'Line downtime'!A:M,9,FALSE),0)+IFERROR(VLOOKUP(C12,'Line downtime'!A:M,10,FALSE),0)+IFERROR(VLOOKUP(C12,'Line downtime'!A:M,11,FALSE),0)+IFERROR(VLOOKUP(C12,'Line downtime'!A:M,12,FALSE),0)+IFERROR(VLOOKUP(C12,'Line downtime'!A:M,13,FALSE),0) -> 15 | K12: =H12/(G12-J12) -> 1 | L12: =IFERROR(VLOOKUP($C12,'Line downtime'!$A:$M,3,FALSE),0) -> 0 | M12: =IFERROR(VLOOKUP($C12,'Line downtime'!$A:$M,6,FALSE),0) -> 0 | N12: =IFERROR(VLOOKUP($C12,'Line downtime'!$A:$M,7,FALSE),0) -> 0 | O12: =IFERROR(VLOOKUP($C12,'Line downtime'!$A:$M,9,FALSE),0) -> 0 | P12: =IFERROR(VLOOKUP($C12,'Line downtime'!$A:$M,11,FALSE),0) -> 0 | Q12: =IFERROR(VLOOKUP($C12,'Line downtime'!$A:$M,12,FALSE),0) -> 0
A13: 45534 | B13: CO-600 | C13: 422122 | D13: Dennis | E13: 0.44236111 | F13: 0.50138889 | G13: =HOUR(F13-E13)*60+MINUTE(F13-E13) -> 85 | H13: =VLOOKUP(B13,Products!A:D,4,FALSE) -> 60 | I13: =H13/G13 -> 0.70588235 | J13: =IFERROR(VLOOKUP(C13,'Line downtime'!A:M,2,FALSE),0)+IFERROR(VLOOKUP(C13,'Line downtime'!A:M,3,FALSE),0)+IFERROR(VLOOKUP(C13,'Line downtime'!A:M,4,FALSE),0)+IFERROR(VLOOKUP(C13,'Line downtime'!A:M,5,FALSE),0)+IFERROR(VLOOKUP(C13,'Line downtime'!A:M,6,FALSE),0)+IFERROR(VLOOKUP(C13,'Line downtime'!A:M,7,FALSE),0)+IFERROR(VLOOKUP(C13,'Line downtime'!A:M,8,FALSE),0)+IFERROR(VLOOKUP(C13,'Line downtime'!A:M,9,FALSE),0)+IFERROR(VLOOKUP(C13,'Line downtime'!A:M,10,FALSE),0)+IFERROR(VLOOKUP(C13,'Line downtime'!A:M,11,FALSE),0)+IFERROR(VLOOKUP(C13,'Line downtime'!A:M,12,FALSE),0)+IFERROR(VLOOKUP(C13,'Line downtime'!A:M,13,FALSE),0) -> 25 | K13: =H13/(G13-J13) -> 1 | L13: =IFERROR(VLOOKUP($C13,'Line downtime'!$A:$M,3,FALSE),0) -> 0 | M13: =IFERROR(VLOOKUP($C13,'Line downtime'!$A:$M,6,FALSE),0) -> 0 | N13: =IFERROR(VLOOKUP($C13,'Line downtime'!$A:$M,7,FALSE),0) -> 0 | O13: =IFERROR(VLOOKUP($C13,'Line downtime'!$A:$M,9,FALSE),0) -> 0 | P13: =IFERROR(VLOOKUP($C13,'Line downtime'!$A:$M,11,FALSE),0) -> 0 | Q13: =IFERROR(VLOOKUP($C13,'Line downtime'!$A:$M,12,FALSE),0) -> 0
... A39: 45538 | B39: CO-2L | C39: 422148 | D39: Mac | E39: 0.95486111 | F39: 1.0451389 | G39: =HOUR(F39-E39)*60+MINUTE(F39-E39) -> 130 | H39: =VLOOKUP(B39,Products!A:D,4,FALSE) -> 98 | I39: =H39/G39 -> 0.75384615 | J39: =IFERROR(VLOOKUP(C39,'Line downtime'!A:M,2,FALSE),0)+IFERROR(VLOOKUP(C39,'Line downtime'!A:M,3,FALSE),0)+IFERROR(VLOOKUP(C39,'Line downtime'!A:M,4,FALSE),0)+IFERROR(VLOOKUP(C39,'Line downtime'!A:M,5,FALSE),0)+IFERROR(VLOOKUP(C39,'Line downtime'!A:M,6,FALSE),0)+IFERROR(VLOOKUP(C39,'Line downtime'!A:M,7,FALSE),0)+IFERROR(VLOOKUP(C39,'Line downtime'!A:M,8,FALSE),0)+IFERROR(VLOOKUP(C39,'Line downtime'!A:M,9,FALSE),0)+IFERROR(VLOOKUP(C39,'Line downtime'!A:M,10,FALSE),0)+IFERROR(VLOOKUP(C39,'Line downtime'!A:M,11,FALSE),0)+IFERROR(VLOOKUP(C39,'Line downtime'!A:M,12,FALSE),0)+IFERROR(VLOOKUP(C39,'Line downtime'!A:M,13,FALSE),0) -> 32 | K39: =H39/(G39-J39) -> 1 | L39: =IFERROR(VLOOKUP($C39,'Line downtime'!$A:$M,3,FALSE),0) -> 0 | M39: =IFERROR(VLOOKUP($C39,'Line downtime'!$A:$M,6,FALSE),0) -> 0 | N39: =IFERROR(VLOOKUP($C39,'Line downtime'!$A:$M,7,FALSE),0) -> 0 | O39: =IFERROR(VLOOKUP($C39,'Line downtime'!$A:$M,9,FALSE),0) -> 7 | P39: =IFERROR(VLOOKUP($C39,'Line downtime'!$A:$M,11,FALSE),0) -> 0 | Q39: =IFERROR(VLOOKUP($C39,'Line downtime'!$A:$M,12,FALSE),0) -> 0
I40: =AVERAGE(I2:I39) -> 0.67076697
A42: Operator | B42: Avg Efficiency % | C42: Avg Downtime (min) | D42: Batch Change | E42: Product Spill | F42: Machine Adj | G42: Batch Code Error | H42: Calibration Error | I42: Label Switch
A43: Mac | B43: =AVERAGEIF($D$2:$D$39,A43,$I$2:$I$39) -> 0.63257853 | C43: =AVERAGEIF($D$2:$D$39,A43,$J$2:$J$39) -> 41.5 | D43: =SUMIF($D$2:$D$39,A43,$L$2:$L$39) -> 130 | E43: =SUMIF($D$2:$D$39,A43,$M$2:$M$39) -> 0 | F43: =SUMIF($D$2:$D$39,A43,$N$2:$N$39) -> 15 | G43: =SUMIF($D$2:$D$39,A43,$O$2:$O$39) -> 47 | H43: =SUMIF($D$2:$D$39,A43,$P$2:$P$39) -> 0 | I43: =SUMIF($D$2:$D$39,A43,$Q$2:$Q$39) -> 0
A44: Charlie | B44: =AVERAGEIF($D$2:$D$39,A44,$I$2:$I$39) -> 0.70973001 | C44: =AVERAGEIF($D$2:$D$39,A44,$J$2:$J$39) -> 34.909091 | D44: =SUMIF($D$2:$D$39,A44,$L$2:$L$39) -> 10 | E44: =SUMIF($D$2:$D$39,A44,$M$2:$M$39) -> 22 | F44: =SUMIF($D$2:$D$39,A44,$N$2:$N$39) -> 118 | G44: =SUMIF($D$2:$D$39,A44,$O$2:$O$39) -> 44 | H44: =SUMIF($D$2:$D$39,A44,$P$2:$P$39) -> 24 | I44: =SUMIF($D$2:$D$39,A44,$Q$2:$Q$39) -> 10
A45: Dee | B45: =AVERAGEIF($D$2:$D$39,A45,$I$2:$I$39) -> 0.66809779 | C45: =AVERAGEIF($D$2:$D$39,A45,$J$2:$J$39) -> 33.636364 | D45: =SUMIF($D$2:$D$39,A45,$L$2:$L$39) -> 20 | E45: =SUMIF($D$2:$D$39,A45,$M$2:$M$39) -> 15 | F45: =SUMIF($D$2:$D$39,A45,$N$2:$N$39) -> 79 | G45: =SUMIF($D$2:$D$39,A45,$O$2:$O$39) -> 30 | H45: =SUMIF($D$2:$D$39,A45,$P$2:$P$39) -> 25 | I45: =SUMIF($D$2:$D$39,A45,$Q$2:$Q$39) -> 23
A46: Dennis | B46: =AVERAGEIF($D$2:$D$39,A46,$I$2:$I$39) -> 0.65905133 | C46: =AVERAGEIF($D$2:$D$39,A46,$J$2:$J$39) -> 37.75 | D46: =SUMIF($D$2:$D$39,A46,$L$2:$L$39) -> 0 | E46: =SUMIF($D$2:$D$39,A46,$M$2:$M$39) -> 20 | F46: =SUMIF($D$2:$D$39,A46,$N$2:$N$39) -> 120 | G46: =SUMIF($D$2:$D$39,A46,$O$2:$O$39) -> 24 | H46: =SUMIF($D$2:$D$39,A46,$P$2:$P$39) -> 0 | I46: =SUMIF($D$2:$D$39,A46,$Q$2:$Q$39) -> 0

Sheet Dashboard
A1: Operator | B1: Avg Efficiency % | F1: Downtime Factor | G1: Total Minutes | K1: Operator | L1: Batch Change | M1: Product Spill | N1: Machine Adj | O1: Batch Code Error | P1: Callibration Error | Q1: Label Switch
A2: Mac | B2: 0.63257853 | F2: Factor 4: Inventory Shortage | G2: 229 | K2: Mac | L2: 130 | M2: 0 | N2: 15 | O2: 47 | P2: 0 | Q2: 0
A3: Charlie | B3: 0.70973001 | F3: Factor 5: Product Spill | G3: 338 | K3: Charlie | L3: 10 | M3: 22 | N3: 118 | O3: 44 | P3: 24 | Q3: 10
A4: Dee | B4: 0.66809779 | F4: Factor 7: Machine Failure | G4: 261 | K4: Dee | L4: 20 | M4: 15 | N4: 79 | O4: 30 | P4: 25 | Q4: 23
A5: Dennis | B5: 0.65905133 | K5: Dennis | L5: 0 | M5: 20 | N5: 120 | O5: 24 | P5: 0 | Q5: 0
